<mujoco model="humanloco2d">
  <compiler angle="degree" coordinate="local" inertiafromgeom="false"/>
  <default>
    <joint armature="0" damping="0" limited="true"/>
    <geom conaffinity="0" condim="3" contype="1" density="1000" friction=".7 .1 .1" rgba="0.8 0.6 .4 1"/>
  </default>
  <option integrator="RK4" timestep="0.002"/>
  <worldbody>
    <light cutoff="100" diffuse="1 1 1" dir="-0 0 -1.3" directional="true" exponent="1" pos="0 0 1.3" specular=".1 .1 .1"/>
    <geom conaffinity="1" condim="3" name="floor" pos="0 0 0" rgba="0.8 0.9 0.8 1" size="40 40 40" type="plane" material="MatPlane"/>
    <body name="torso" pos="0 0 1.31">
      <camera name="track" mode="trackcom" pos="0 -3 1" xyaxes="1 0 0 0 0 1"/>
      <joint armature="0" axis="1 0 0" damping="0" limited="false" name="rootx" pos="0 0 0" stiffness="0" type="slide"/>
      <joint armature="0" axis="0 0 1" damping="0" limited="false" name="rootz" pos="0 0 0" ref="1.25" stiffness="0" type="slide"/>
      <joint armature="0" axis="0 1 0" damping="0" limited="false" name="roottheta" pos="0 0 1.25" stiffness="0" type="hinge"/>
      <inertial pos="0 0 0" mass="54" diaginertia="4.0 3.0 1.0"/>
      <geom friction="0.9" name="torso_geom" pos="0 0 0.075" size="0.1 0.2 0.425" type="ellipsoid"/>
      <body name="r_thigh" pos="0 -.1 -0.35">
        <joint axis="0 1 0" name="r_hip" pos="0 0 0" range="-120 30" type="hinge"/>
        <inertial pos="0 0 -0.16" mass="8" diaginertia="0.15 0.15 0.03"/>
        <geom friction="0.9" fromto="0 0 0 0 0 -0.44" name="r_thigh_geom" size="0.06" type="capsule"/>
        <body name="r_shank" pos="0 0 -0.44">
          <joint axis="0 -1 0" name="r_knee" pos="0 0 0" range="-150 0" type="hinge"/>
          <inertial pos="0 0 -0.16" mass="3.75" diaginertia="0.05 0.05 0.003"/>
          <geom friction="0.9" fromto="0 0 0 0 0 -0.44" name="r_shank_geom" size="0.04" type="capsule"/>
          <body name="r_foot" pos="0 0 -0.44">
            <joint axis="0 1 0" name="r_ankle" pos="0 0 0" range="-30 60" type="hinge"/>
            <inertial pos="0.02 0 -0.01" mass="1.25" diaginertia="0.0007 0.005 0.005"/>
            <geom friction="0.9" name="r_foot_geom" pos="0.06 0 -0.04" size="0.1 0.03 0.01" type="box"/>
            <geom friction="2.0" fromto="-0.04 -0.025 -0.05 -0.04 0.025 -0.05" name="r_foot_geom1" size="0.03" type="capsule"/>
            <geom friction="2.0" fromto="0.16 -0.05 -0.05 0.16 0.05 -0.05" name="r_foot_geom2" size="0.03" type="capsule"/>
          </body>
        </body>
      </body>
      <!-- left leg is symmetric to the right-->
      <body name="l_thigh" pos="0 .1 -0.35">
        <joint axis="0 1 0" name="l_hip" pos="0 0 0" range="-120 30" type="hinge"/>
        <inertial pos="0 0 -0.16" mass="8" diaginertia="0.15 0.15 0.03"/>
        <geom friction="0.9" fromto="0 0 0 0 0 -0.44" name="l_thigh_geom" size="0.06" type="capsule"/>
        <body name="l_shank" pos="0 0 -0.44">
          <joint axis="0 -1 0" name="l_knee" pos="0 0 0" range="-150 0" type="hinge"/>
          <inertial pos="0 0 -0.16" mass="3.75" diaginertia="0.05 0.05 0.003"/>
          <geom friction="0.9" fromto="0 0 0 0 0 -0.44" name="l_shank_geom" size="0.04" type="capsule"/>
          <body name="l_foot" pos="0 0 -0.44">
            <joint axis="0 1 0" name="l_ankle" pos="0 0 0" range="-30 60" type="hinge"/>
            <inertial pos="0.02 0 -0.01" mass="1.25" diaginertia="0.0007 0.005 0.005"/>
            <geom friction="0.9" name="l_foot_geom" pos="0.06 0 -0.04" size="0.1 0.03 0.01" type="box"/>
            <geom friction="2.0" fromto="-0.04 -0.025 -0.05 -0.04 0.025 -0.05" name="l_foot_geom1" size="0.03" type="capsule"/>
            <geom friction="2.0" fromto="0.16 -0.05 -0.05 0.16 0.05 -0.05" name="l_foot_geom2" size="0.03" type="capsule"/>
          </body>
        </body>
      </body>

    </body>
  </worldbody>
  <actuator>    
    <motor ctrllimited="false" gear="1.0" joint="r_hip"/>
    <motor ctrllimited="false" gear="1.0" joint="r_knee"/>
    <motor ctrllimited="false" gear="1.0" joint="r_ankle"/>
    <motor ctrllimited="false" gear="1.0" joint="l_hip"/>
    <motor ctrllimited="false" gear="1.0" joint="l_knee"/>
    <motor ctrllimited="false" gear="1.0" joint="l_ankle"/>
  </actuator>
    <asset>
        <texture type="skybox" builtin="gradient" rgb1=".4 .5 .6" rgb2="0 0 0" width="100" height="100"/>
        <texture builtin="flat" height="1278" mark="cross" markrgb="1 1 1" name="texgeom" random="0.01" rgb1="0.8 0.6 0.4" rgb2="0.8 0.6 0.4" type="cube" width="127"/>
        <texture builtin="checker" height="100" name="texplane" rgb1="0 0 0" rgb2="0.8 0.8 0.8" type="2d" width="100"/>
        <material name="MatPlane" reflectance="0.5" shininess="1" specular="1" texrepeat="60 60" texture="texplane"/>
        <material name="geom" texture="texgeom" texuniform="true"/>
    </asset>
</mujoco>